Error: 
Timestamp: 2025-05-05 10:04:12

Stack trace:
Traceback (most recent call last):
  File "/Users/aravind/Desktop/Message-Analyser/scripts/api/server.py", line 145, in analyze_conversations
    list_of_raw_outputs = process_conversations(model_name, list_of_conversations, usecase, prompt)
  File "/Library/Frameworks/Python.framework/Versions/3.10/lib/python3.10/bdb.py", line 96, in trace_dispatch
    return self.dispatch_exception(frame, arg)
  File "/Library/Frameworks/Python.framework/Versions/3.10/lib/python3.10/bdb.py", line 176, in dispatch_exception
    if self.quitting: raise BdbQuit
bdb.BdbQuit
